Workbook

Sheet Read Me
A1: Open Federal Construction & Steel Bids
A2: 128 open bids, pulled 2026-10-03 by Set-Aside Radar from SAM.gov
A4: The tabs
A5: All Open Bids: every open bid, soonest deadline first, with days left and a link to the notice.
A6: Steel & Metals: the same, only structural steel, concrete, masonry, roofing and metal fabrication.
A7: By Trade: how many open bids each trade has, split into set-asides and open-to-anyone.
A9: "Who can bid" tells you who is eligible. Green = any business can bid, no certification needed.
A10: The rest are set aside: small businesses, veteran-owned, 8(a), women-owned and so on.
A12: PBM Consulting Service · pbmconsultingservice.com · 6814 Chris Madsen Rd, Guthrie, OK 73044
A14: Source: SAM.gov contract opportunities (public U.S. government data), as stored by Set-Aside Radar.
A15: Radar keeps every set-aside notice; open-to-anyone notices appear only when SAM.gov marks them "No set aside used",
A16: so the open-to-anyone list is a partial count. Check each notice on SAM.gov before bidding: terms can change.

Sheet All Open Bids
A1: Due | B1: Days left | C1: Job | D1: Trade | E1: Trade group | F1: Where | G1: Who can bid | H1: Notice type | I1: Agency | J1: NAICS | K1: Notice
A2: 46300 | B2: =IF(A2="","",A2-TODAY()) | C2: Atlantic Intracoastal Waterway Maintenance Dredging | D2: Other heavy & civil | E2: Other heavy & civil | F2: NC | G2: Small business | H2: Solicitation | I2: DEPT OF DEFENSE | J2: 237990 | K2: =HYPERLINK("https://sam.gov/opp/08164338450e4a1381c731f91cf0b4fa/view","Open on SAM.gov")
A3: 46300 | B3: =IF(A3="","",A3-TODAY()) | C3: Lower Monumental PH HVAC System Upgrade | D3: Plumbing, heating & A/C | E3: Building equipment (electrical, plumbing, HVAC) | F3: Kahlotus, WA | G3: Any business (no set-aside) | H3: Solicitation | I3: DEPT OF DEFENSE | J3: 238220 | K3: =HYPERLINK("https://sam.gov/opp/e217a7fed88c47d1abee64d52bd8ad5b/view","Open on SAM.gov")
A4: 46300 | B4: =IF(A4="","",A4-TODAY()) | C4: National Enterprise Dredging Center Scope Dredge to Budget Shallow Draft | D4: Other heavy & civil | E4: Other heavy & civil | F4: TX | G4: Small business | H4: Sources sought | I4: DEPT OF DEFENSE | J4: 237990 | K4: =HYPERLINK("https://sam.gov/opp/58420728dbc4429fa83d66599758c0e4/view","Open on SAM.gov")
A5: 46300 | B5: =IF(A5="","",A5-TODAY()) | C5: REPAIR AC PAVING | D5: All other specialty trades | E5: Other specialty trades | F5: CA | G5: Small business | H5: Combined synopsis/solicitation | I5: DEPT OF DEFENSE | J5: 238990 | K5: =HYPERLINK("https://sam.gov/opp/b45d33680638429590bf29cadd47e788/view","Open on SAM.gov")
A6: 46300 | B6: =IF(A6="","",A6-TODAY()) | C6: Y1DA--Drop Ceiling Demo, Disinfect and Replace at the Brooklyn VA Medical Cente | D6: Commercial & institutional building | E6: Commercial & institutional building | F6: Brooklyn, NY | G6: Service-disabled veteran-owned small business | H6: Combined synopsis/solicitation | I6: VETERANS AFFAIRS, DEPARTMENT OF | J6: 236220 | K6: =HYPERLINK("https://sam.gov/opp/de6f165e39cf4002a1405eef143fd63c/view","Open on SAM.gov")
A7: 46301 | B7: =IF(A7="","",A7-TODAY()) | C7: GAOA Cordova Outhouse Replacement Chugach NF | D7: Other heavy & civil | E7: Other heavy & civil | F7: Cordova, AK | G7: Small business | H7: Solicitation | I7: AGRICULTURE, DEPARTMENT OF | J7: 237990 | K7: =HYPERLINK("https://sam.gov/opp/57ceab2afa6d451a95632e844d5645fa/view","Open on SAM.gov")
A8: 46301 | B8: =IF(A8="","",A8-TODAY()) | C8: MINOS High Bay Roof Replacement & Masonry Wall Repair | D8: Commercial & institutional building | E8: Commercial & institutional building | F8: Batavia, IL | G8: Small business | H8: Solicitation | I8: ENERGY, DEPARTMENT OF | J8: 236220 | K8: =HYPERLINK("https://sam.gov/opp/a89a0559d74b414a88db239e0641c114/view","Open on SAM.gov")
A9: 46301 | B9: =IF(A9="","",A9-TODAY()) | C9: NAICS 237990 PSC Y1PZ--CONS: 909CM3030 Fort Custer NC - Cemetery Expansion and S | D9: Other heavy & civil | E9: Other heavy & civil | F9: MI | G9: Service-disabled veteran-owned small business | H9: Solicitation | I9: VETERANS AFFAIRS, DEPARTMENT OF | J9: 237990 | K9: =HYPERLINK("https://sam.gov/opp/38d97f11609848a08904a81fc82a1251/view","Open on SAM.gov")
A10: 46302 | B10: =IF(A10="","",A10-TODAY()) | C10: FY27 McConnell AFB - Multiple Award Construction Contract (MACC) | D10: Commercial & institutional building | E10: Commercial & institutional building | F10: KS | G10: Small business | H10: Solicitation | I10: DEPT OF DEFENSE | J10: 236220 | K10: =HYPERLINK("https://sam.gov/opp/9e583346d2d944e192fb119cc0184162/view","Open on SAM.gov")
A11: 46302 | B11: =IF(A11="","",A11-TODAY()) | C11: GAOA Trujillo Meadows Old Toilet Building Replacement RGNF | D11: Prefab metal buildings & components | E11: Architectural & structural metals | F11: Del Norte, CO | G11: Small business | H11: Combined synopsis/solicitation | I11: AGRICULTURE, DEPARTMENT OF | J11: 332311 | K11: =HYPERLINK("https://sam.gov/opp/22fbb1bdc374408582e4693b27edc98e/view","Open on SAM.gov")
A12: 46302 | B12: =IF(A12="","",A12-TODAY()) | C12: Testing & Inspecting, Preventative Maintenance (PM), Corrective Repairs, and Ser | D12: Plumbing, heating & A/C | E12: Building equipment (electrical, plumbing, HVAC) | F12: Dallas, TX | G12: Service-disabled veteran-owned small business | H12: Solicitation | I12: VETERANS AFFAIRS, DEPARTMENT OF | J12: 238220 | K12: =HYPERLINK("https://sam.gov/opp/f346fbdede3749e49f55e9272b7951be/view","Open on SAM.gov")
A13: 46302 | B13: =IF(A13="","",A13-TODAY()) | C13: Vehicle Maintenance Shop, Kadena Air Base | D13: Commercial & institutional building | E13: Commercial & institutional building | F13: Kadena Air Base, JP-47 | G13: Any business (no set-aside) | H13: Sources sought | I13: DEPT OF DEFENSE | J13: 236220 | K13: =HYPERLINK("https://sam.gov/opp/1b0fb8f37b094038bd076033fef4c019/view","Open on SAM.gov")
A14: 46302 | B14: =IF(A14="","",A14-TODAY()) | C14: Y--Rehabilitation of Water and Wastewater System | D14: Water & sewer lines | E14: Utility systems | F14: See notice | G14: Small business | H14: Solicitation | I14: INTERIOR, DEPARTMENT OF THE | J14: 237110 | K14: =HYPERLINK("https://sam.gov/opp/6fe9ebf7308c4c45abc2407f48e0028f/view","Open on SAM.gov")
A15: 46303 | B15: =IF(A15="","",A15-TODAY()) | C15: CO NP BLCA 10(1) South Rim Drive | D15: Highway, street & bridge | E15: Highway, street & bridge | F15: Montrose, CO | G15: Small business | H15: Combined synopsis/solicitation | I15: TRANSPORTATION, DEPARTMENT OF | J15: 237310 | K15: =HYPERLINK("https://sam.gov/opp/8017030241ca445f932342aaaafee2ad/view","Open on SAM.gov")
A16: 46303 | B16: =IF(A16="","",A16-TODAY()) | C16: CO NP BLCA 10(1) South Rim Drive | D16: Highway, street & bridge | E16: Highway, street & bridge | F16: Montrose, CO | G16: Small business | H16: Combined synopsis/solicitation | I16: TRANSPORTATION, DEPARTMENT OF | J16: 237310 | K16: =HYPERLINK("https://sam.gov/opp/c64ad7b388eb45508fbf6c83c5e17976/view","Open on SAM.gov")
A17: 46303 | B17: =IF(A17="","",A17-TODAY()) | C17: KB Duct List | D17: Sheet metal work | E17: Architectural & structural metals | F17: OK | G17: Small business | H17: Combined synopsis/solicitation | I17: DEPT OF DEFENSE | J17: 332322 | K17: =HYPERLINK("https://sam.gov/opp/58ac093c4794430b88d68d95431e4fdb/view","Open on SAM.gov")
A18: 46303 | B18: =IF(A18="","",A18-TODAY()) | C18: Quick Acting Watertight Scuttle | D18: Metal windows & doors | E18: Architectural & structural metals | F18: See notice | G18: Small business | H18: Combined synopsis/solicitation | I18: DEPT OF DEFENSE | J18: 332321 | K18: =HYPERLINK("https://sam.gov/opp/8323bbe78aa74155bbc165ffb2713d07/view","Open on SAM.gov")
A19: 46303 | B19: =IF(A19="","",A19-TODAY()) | C19: VA STLHCS-JC Northeast Parking Structure Solicitation | D19: Commercial & institutional building | E19: Commercial & institutional building | F19: MO | G19: Service-disabled veteran-owned small business | H19: Solicitation | I19: DEPT OF DEFENSE | J19: 236220 | K19: =HYPERLINK("https://sam.gov/opp/59a9564b2c5d49e7a3e5f0c6eea9ea45/view","Open on SAM.gov")
A20: 46303 | B20: =IF(A20="","",A20-TODAY()) | C20: Y--BRCA 318695 - CONSTRUCTION | D20: Water & sewer lines | E20: Utility systems | F20: See notice | G20: Small business | H20: Solicitation | I20: INTERIOR, DEPARTMENT OF THE | J20: 237110 | K20: =HYPERLINK("https://sam.gov/opp/97a14fd9e1174ce88697722e189b65ba/view","Open on SAM.gov")
A21: 46303 | B21: =IF(A21="","",A21-TODAY()) | C21: Z--Folsom Warehouse Bridge Crane Replacement | D21: Other heavy & civil | E21: Other heavy & civil | F21: See notice | G21: Service-disabled veteran-owned small business | H21: Solicitation | I21: INTERIOR, DEPARTMENT OF THE | J21: 237990 | K21: =HYPERLINK("https://sam.gov/opp/35f146c439fa4c40b787573b1055d857/view","Open on SAM.gov")
A22: 46304 | B22: =IF(A22="","",A22-TODAY()) | C22: 53--DOOR,ACCESS,WEAPON SYS | D22: Metal windows & doors | E22: Architectural & structural metals | F22: See notice | G22: Small business | H22: Combined synopsis/solicitation | I22: DEPT OF DEFENSE | J22: 332321 | K22: =HYPERLINK("https://sam.gov/opp/91b65350b9fa4ed7a5414ae473464548/view","Open on SAM.gov")
A23: 46304 | B23: =IF(A23="","",A23-TODAY()) | C23: BEJ Courtesy Dock Supply and Installation | D23: Other heavy & civil | E23: Other heavy & civil | F23: See notice | G23: Small business | H23: Solicitation | I23: DEPT OF DEFENSE | J23: 237990 | K23: =HYPERLINK("https://sam.gov/opp/4944c6c31282463a9ab47d67b90abfb8/view","Open on SAM.gov")
A24: 46304 | B24: =IF(A24="","",A24-TODAY()) | C24: BEJ Courtesy Dock Supply and Installation | D24: Other heavy & civil | E24: Other heavy & civil | F24: See notice | G24: Small business | H24: Solicitation | I24: DEPT OF DEFENSE | J24: 237990 | K24: =HYPERLINK("https://sam.gov/opp/9f7b3027da904c42a5c1e9c8cb3b4058/view","Open on SAM.gov")
A25: 46304 | B25: =IF(A25="","",A25-TODAY()) | C25: Construct Concrete Targets | D25: Concrete foundation & structure | E25: Foundation, structure & exterior | F25: FL | G25: Small business | H25: Combined synopsis/solicitation | I25: DEPT OF DEFENSE | J25: 238110 | K25: =HYPERLINK("https://sam.gov/opp/d51fcf5dcb2941abb432014a55a623ad/view","Open on SAM.gov")
A26: 46304 | B26: =IF(A26="","",A26-TODAY()) | C26: Construction- NUWCDIVNPT- Vaporizer Enclosure (Design/Build) | D26: Commercial & institutional building | E26: Commercial & institutional building | F26: Newport, RI | G26: Small business | H26: Combined synopsis/solicitation | I26: DEPT OF DEFENSE | J26: 236220 | K26: =HYPERLINK("https://sam.gov/opp/d5856d8a91d3445887652db4f6bf8a06/view","Open on SAM.gov")
A27: 46304 | B27: =IF(A27="","",A27-TODAY()) | C27: DISA FY26 ROOF REPAIRS AT FORT MEADE, MARYLAND | D27: Roofing | E27: Foundation, structure & exterior | F27: MD | G27: Small business | H27: Solicitation | I27: DEPT OF DEFENSE | J27: 238160 | K27: =HYPERLINK("https://sam.gov/opp/b2b54eac8d7a4c35b6a2846fa25f4e63/view","Open on SAM.gov")
A28: 46304 | B28: =IF(A28="","",A28-TODAY()) | C28: J045--Install Chill Water System Filtration & Steam Condensate Polisher | D28: Plumbing, heating & A/C | E28: Building equipment (electrical, plumbing, HVAC) | F28: Dallas, TX | G28: Service-disabled veteran-owned small business | H28: Combined synopsis/solicitation | I28: VETERANS AFFAIRS, DEPARTMENT OF | J28: 238220 | K28: =HYPERLINK("https://sam.gov/opp/c3e9ff2124484cecafb56bdaa4d8e0c5/view","Open on SAM.gov")
A29: 46304 | B29: =IF(A29="","",A29-TODAY()) | C29: J059--Albany Transformer Testing & Service | D29: Electrical | E29: Building equipment (electrical, plumbing, HVAC) | F29: Albany, NY | G29: Service-disabled veteran-owned small business | H29: Presolicitation | I29: VETERANS AFFAIRS, DEPARTMENT OF | J29: 238210 | K29: =HYPERLINK("https://sam.gov/opp/e7a615cf8cae4bf189b2274ce7520c7c/view","Open on SAM.gov")
A30: 46304 | B30: =IF(A30="","",A30-TODAY()) | C30: Replace Dental Vacuum Piping | D30: Commercial & institutional building | E30: Commercial & institutional building | F30: North Las Vegas, NV | G30: Any business (no set-aside) | H30: Sources sought | I30: VETERANS AFFAIRS, DEPARTMENT OF | J30: 236220 | K30: =HYPERLINK("https://sam.gov/opp/e22cfb288b8d4cba8180bffb51c326e6/view","Open on SAM.gov")
A31: 46304 | B31: =IF(A31="","",A31-TODAY()) | C31: Y1DA--Sidewalk Replacement Throughout Lyons Campus | D31: Highway, street & bridge | E31: Highway, street & bridge | F31: See notice | G31: Service-disabled veteran-owned small business | H31: Presolicitation | I31: VETERANS AFFAIRS, DEPARTMENT OF | J31: 237310 | K31: =HYPERLINK("https://sam.gov/opp/a8daacb74509400f97d1a64e370cd076/view","Open on SAM.gov")
A32: 46304 | B32: =IF(A32="","",A32-TODAY()) | C32: Y1DZ--519-371 Construct New CLC Phase III Minor Construction - Big Spring, TX V | D32: Commercial & institutional building | E32: Commercial & institutional building | F32: Big Spring, TX | G32: Service-disabled veteran-owned small business | H32: Solicitation | I32: VETERANS AFFAIRS, DEPARTMENT OF | J32: 236220 | K32: =HYPERLINK("https://sam.gov/opp/f1634437c33b4a78989b5d28354f0e0f/view","Open on SAM.gov")
A33: 46307 | B33: =IF(A33="","",A33-TODAY()) | C33: CON | Z1DA | REPLACE OR CHILLERS | 580-23-105 | PRESOLICITATION | D33: Plumbing, heating & A/C | E33: Building equipment (electrical, plumbing, HVAC) | F33: Houston, TX | G33: Service-disabled veteran-owned small business | H33: Presolicitation | I33: VETERANS AFFAIRS, DEPARTMENT OF | J33: 238220 | K33: =HYPERLINK("https://sam.gov/opp/a24392fb76014de8a575c857b8160e41/view","Open on SAM.gov")
A34: 46307 | B34: =IF(A34="","",A34-TODAY()) | C34: Green Mountain National Forest Storage tank cleaning and inspection at Hapgood P | D34: Plumbing, heating & A/C | E34: Building equipment (electrical, plumbing, HVAC) | F34: Peru, VT | G34: Small business | H34: Solicitation | I34: AGRICULTURE, DEPARTMENT OF | J34: 238220 | K34: =HYPERLINK("https://sam.gov/opp/e4ff995b42c941d7924c5b60195d01de/view","Open on SAM.gov")
A35: 46307 | B35: =IF(A35="","",A35-TODAY()) | C35: Y1DA | 521-24-102 | Renovate Wards 2K and 2B for Optometry/Ophthalmology Clinica | D35: Commercial & institutional building | E35: Commercial & institutional building | F35: AL | G35: Service-disabled veteran-owned small business | H35: Presolicitation | I35: VETERANS AFFAIRS, DEPARTMENT OF | J35: 236220 | K35: =HYPERLINK("https://sam.gov/opp/6409b3ce7f93443b86e524ae3c52f754/view","Open on SAM.gov")
A36: 46307 | B36: =IF(A36="","",A36-TODAY()) | C36: Z2FZ--590-24-450 Renovate Transitional Residences | D36: Residential remodeling | E36: Residential building | F36: Hampton, VA | G36: Service-disabled veteran-owned small business | H36: Solicitation | I36: VETERANS AFFAIRS, DEPARTMENT OF | J36: 236118 | K36: =HYPERLINK("https://sam.gov/opp/ceb638cfd94a452abecbeba10d235d60/view","Open on SAM.gov")
A37: 46308 | B37: =IF(A37="","",A37-TODAY()) | C37: 42--FACEPIECE,BREATHING EQ | D37: All other specialty trades | E37: Other specialty trades | F37: See notice | G37: Small business | H37: Combined synopsis/solicitation | I37: DEPT OF DEFENSE | J37: 238990 | K37: =HYPERLINK("https://sam.gov/opp/e5c3b77964a64e8b82f55c5320566b51/view","Open on SAM.gov")
A38: 46308 | B38: =IF(A38="","",A38-TODAY()) | C38: 53--STUD ASSEMBLY,TURNLOCK | D38: Sheet metal work | E38: Architectural & structural metals | F38: See notice | G38: Small business | H38: Combined synopsis/solicitation | I38: DEPT OF DEFENSE | J38: 332322 | K38: =HYPERLINK("https://sam.gov/opp/eb2cc7afab954bd8a067d6c7e423d340/view","Open on SAM.gov")
A39: 46308 | B39: =IF(A39="","",A39-TODAY()) | C39: 54--PANEL ASSEMBLY | D39: Prefab metal buildings & components | E39: Architectural & structural metals | F39: See notice | G39: Service-disabled veteran-owned small business | H39: Combined synopsis/solicitation | I39: DEPT OF DEFENSE | J39: 332311 | K39: =HYPERLINK("https://sam.gov/opp/c954a530fb6243de9b71381cd435fa4a/view","Open on SAM.gov")
A40: 46308 | B40: =IF(A40="","",A40-TODAY()) | C40: Alaska Construction Multiple Award Task Order Contract (MATOC) | D40: Commercial & institutional building | E40: Commercial & institutional building | F40: See notice | G40: Small business | H40: Combined synopsis/solicitation | I40: DEPT OF DEFENSE | J40: 236220 | K40: =HYPERLINK("https://sam.gov/opp/77a1c56c6d4344c780880b63c79b542c/view","Open on SAM.gov")
...

Sheet Steel & Metals
A1: Due | B1: Days left | C1: Job | D1: Trade | E1: Trade group | F1: Where | G1: Who can bid | H1: Notice type | I1: Agency | J1: NAICS | K1: Notice
A2: 46302 | B2: =IF(A2="","",A2-TODAY()) | C2: GAOA Trujillo Meadows Old Toilet Building Replacement RGNF | D2: Prefab metal buildings & components | E2: Architectural & structural metals | F2: Del Norte, CO | G2: Small business | H2: Combined synopsis/solicitation | I2: AGRICULTURE, DEPARTMENT OF | J2: 332311 | K2: =HYPERLINK("https://sam.gov/opp/22fbb1bdc374408582e4693b27edc98e/view","Open on SAM.gov")
A3: 46303 | B3: =IF(A3="","",A3-TODAY()) | C3: KB Duct List | D3: Sheet metal work | E3: Architectural & structural metals | F3: OK | G3: Small business | H3: Combined synopsis/solicitation | I3: DEPT OF DEFENSE | J3: 332322 | K3: =HYPERLINK("https://sam.gov/opp/58ac093c4794430b88d68d95431e4fdb/view","Open on SAM.gov")
A4: 46303 | B4: =IF(A4="","",A4-TODAY()) | C4: Quick Acting Watertight Scuttle | D4: Metal windows & doors | E4: Architectural & structural metals | F4: See notice | G4: Small business | H4: Combined synopsis/solicitation | I4: DEPT OF DEFENSE | J4: 332321 | K4: =HYPERLINK("https://sam.gov/opp/8323bbe78aa74155bbc165ffb2713d07/view","Open on SAM.gov")
A5: 46304 | B5: =IF(A5="","",A5-TODAY()) | C5: 53--DOOR,ACCESS,WEAPON SYS | D5: Metal windows & doors | E5: Architectural & structural metals | F5: See notice | G5: Small business | H5: Combined synopsis/solicitation | I5: DEPT OF DEFENSE | J5: 332321 | K5: =HYPERLINK("https://sam.gov/opp/91b65350b9fa4ed7a5414ae473464548/view","Open on SAM.gov")
A6: 46304 | B6: =IF(A6="","",A6-TODAY()) | C6: Construct Concrete Targets | D6: Concrete foundation & structure | E6: Foundation, structure & exterior | F6: FL | G6: Small business | H6: Combined synopsis/solicitation | I6: DEPT OF DEFENSE | J6: 238110 | K6: =HYPERLINK("https://sam.gov/opp/d51fcf5dcb2941abb432014a55a623ad/view","Open on SAM.gov")
A7: 46304 | B7: =IF(A7="","",A7-TODAY()) | C7: DISA FY26 ROOF REPAIRS AT FORT MEADE, MARYLAND | D7: Roofing | E7: Foundation, structure & exterior | F7: MD | G7: Small business | H7: Solicitation | I7: DEPT OF DEFENSE | J7: 238160 | K7: =HYPERLINK("https://sam.gov/opp/b2b54eac8d7a4c35b6a2846fa25f4e63/view","Open on SAM.gov")
A8: 46308 | B8: =IF(A8="","",A8-TODAY()) | C8: 53--STUD ASSEMBLY,TURNLOCK | D8: Sheet metal work | E8: Architectural & structural metals | F8: See notice | G8: Small business | H8: Combined synopsis/solicitation | I8: DEPT OF DEFENSE | J8: 332322 | K8: =HYPERLINK("https://sam.gov/opp/eb2cc7afab954bd8a067d6c7e423d340/view","Open on SAM.gov")
A9: 46308 | B9: =IF(A9="","",A9-TODAY()) | C9: 54--PANEL ASSEMBLY | D9: Prefab metal buildings & components | E9: Architectural & structural metals | F9: See notice | G9: Service-disabled veteran-owned small business | H9: Combined synopsis/solicitation | I9: DEPT OF DEFENSE | J9: 332311 | K9: =HYPERLINK("https://sam.gov/opp/c954a530fb6243de9b71381cd435fa4a/view","Open on SAM.gov")
A10: 46311 | B10: =IF(A10="","",A10-TODAY()) | C10: Pharmacy Window | D10: Glass & glazing | E10: Foundation, structure & exterior | F10: Tacoma, WA | G10: Any business (no set-aside) | H10: Sources sought | I10: VETERANS AFFAIRS, DEPARTMENT OF | J10: 238150 | K10: =HYPERLINK("https://sam.gov/opp/784bfcf3756f4303b69a593058cb15ab/view","Open on SAM.gov")
A11: 46321 | B11: =IF(A11="","",A11-TODAY()) | C11: Debris Boom Supply and Install at Harry S. Truman Lake Project | D11: Fabricated structural metal | E11: Architectural & structural metals | F11: Warsaw, MO | G11: Any business (no set-aside) | H11: Combined synopsis/solicitation | I11: DEPT OF DEFENSE | J11: 332312 | K11: =HYPERLINK("https://sam.gov/opp/ef3a7c8b92a142ba9378ee3b2c161eb0/view","Open on SAM.gov")
A12: 46323 | B12: =IF(A12="","",A12-TODAY()) | C12: B. Everett Jordan Concrete Pad Installation | D12: Concrete foundation & structure | E12: Foundation, structure & exterior | F12: See notice | G12: Small business | H12: Solicitation | I12: DEPT OF DEFENSE | J12: 238110 | K12: =HYPERLINK("https://sam.gov/opp/7732b732bff24d72949ed3b00540ec55/view","Open on SAM.gov")
A13: 46325 | B13: =IF(A13="","",A13-TODAY()) | C13: 554-27-117 Conduct Concrete and Civil Site Repairs. | D13: Concrete foundation & structure | E13: Foundation, structure & exterior | F13: Aurora, CO | G13: Service-disabled veteran-owned small business | H13: Solicitation | I13: VETERANS AFFAIRS, DEPARTMENT OF | J13: 238110 | K13: =HYPERLINK("https://sam.gov/opp/d22a0a3205004b37a9ecfd057a8d71f5/view","Open on SAM.gov")
A14: 46325 | B14: =IF(A14="","",A14-TODAY()) | C14: GAOA Remove and Replace Roofing on Island Park Admin Site Housing Units | D14: Roofing | E14: Foundation, structure & exterior | F14: Island Park, ID | G14: Small business | H14: Combined synopsis/solicitation | I14: AGRICULTURE, DEPARTMENT OF | J14: 238160 | K14: =HYPERLINK("https://sam.gov/opp/f2e9d92d3e584a08b05d14d695b92bc8/view","Open on SAM.gov")
A15: 46339 | B15: =IF(A15="","",A15-TODAY()) | C15: Z1DA--542-21-113 | Correct FCA Deficiencies – Repair Water Penetration | NCO | D15: Other foundation, structure & exterior | E15: Foundation, structure & exterior | F15: VA | G15: Service-disabled veteran-owned small business | H15: Presolicitation | I15: VETERANS AFFAIRS, DEPARTMENT OF | J15: 238190 | K15: =HYPERLINK("https://sam.gov/opp/e4cad28918d446b8bd0c77c0f8772f9d/view","Open on SAM.gov")

Sheet By Trade
A1: NAICS group | B1: Trade | C1: Set-aside bids | D1: Open to anyone | E1: Total open
A2: 2361 | B2: Residential building | C2: =COUNTIFS('All Open Bids'!$E$2:$E$129,B2,'All Open Bids'!$G$2:$G$129,"<>Any business (no set-aside)") | D2: =COUNTIFS('All Open Bids'!$E$2:$E$129,B2,'All Open Bids'!$G$2:$G$129,"Any business (no set-aside)") | E2: =C2+D2
A3: 2362 | B3: Commercial & institutional building | C3: =COUNTIFS('All Open Bids'!$E$2:$E$129,B3,'All Open Bids'!$G$2:$G$129,"<>Any business (no set-aside)") | D3: =COUNTIFS('All Open Bids'!$E$2:$E$129,B3,'All Open Bids'!$G$2:$G$129,"Any business (no set-aside)") | E3: =C3+D3
A4: 2371 | B4: Utility systems | C4: =COUNTIFS('All Open Bids'!$E$2:$E$129,B4,'All Open Bids'!$G$2:$G$129,"<>Any business (no set-aside)") | D4: =COUNTIFS('All Open Bids'!$E$2:$E$129,B4,'All Open Bids'!$G$2:$G$129,"Any business (no set-aside)") | E4: =C4+D4
A5: 2373 | B5: Highway, street & bridge | C5: =COUNTIFS('All Open Bids'!$E$2:$E$129,B5,'All Open Bids'!$G$2:$G$129,"<>Any business (no set-aside)") | D5: =COUNTIFS('All Open Bids'!$E$2:$E$129,B5,'All Open Bids'!$G$2:$G$129,"Any business (no set-aside)") | E5: =C5+D5
A6: 2379 | B6: Other heavy & civil | C6: =COUNTIFS('All Open Bids'!$E$2:$E$129,B6,'All Open Bids'!$G$2:$G$129,"<>Any business (no set-aside)") | D6: =COUNTIFS('All Open Bids'!$E$2:$E$129,B6,'All Open Bids'!$G$2:$G$129,"Any business (no set-aside)") | E6: =C6+D6
A7: 2381 | B7: Foundation, structure & exterior | C7: =COUNTIFS('All Open Bids'!$E$2:$E$129,B7,'All Open Bids'!$G$2:$G$129,"<>Any business (no set-aside)") | D7: =COUNTIFS('All Open Bids'!$E$2:$E$129,B7,'All Open Bids'!$G$2:$G$129,"Any business (no set-aside)") | E7: =C7+D7
A8: 2382 | B8: Building equipment (electrical, plumbing, HVAC) | C8: =COUNTIFS('All Open Bids'!$E$2:$E$129,B8,'All Open Bids'!$G$2:$G$129,"<>Any business (no set-aside)") | D8: =COUNTIFS('All Open Bids'!$E$2:$E$129,B8,'All Open Bids'!$G$2:$G$129,"Any business (no set-aside)") | E8: =C8+D8
A9: 2383 | B9: Building finishing | C9: =COUNTIFS('All Open Bids'!$E$2:$E$129,B9,'All Open Bids'!$G$2:$G$129,"<>Any business (no set-aside)") | D9: =COUNTIFS('All Open Bids'!$E$2:$E$129,B9,'All Open Bids'!$G$2:$G$129,"Any business (no set-aside)") | E9: =C9+D9
A10: 2389 | B10: Other specialty trades | C10: =COUNTIFS('All Open Bids'!$E$2:$E$129,B10,'All Open Bids'!$G$2:$G$129,"<>Any business (no set-aside)") | D10: =COUNTIFS('All Open Bids'!$E$2:$E$129,B10,'All Open Bids'!$G$2:$G$129,"Any business (no set-aside)") | E10: =C10+D10
A11: 3323 | B11: Architectural & structural metals | C11: =COUNTIFS('All Open Bids'!$E$2:$E$129,B11,'All Open Bids'!$G$2:$G$129,"<>Any business (no set-aside)") | D11: =COUNTIFS('All Open Bids'!$E$2:$E$129,B11,'All Open Bids'!$G$2:$G$129,"Any business (no set-aside)") | E11: =C11+D11
B12: All trades | C12: =SUM(C2:C11) | D12: =SUM(D2:D11) | E12: =SUM(E2:E11)
A14: Counts come from the All Open Bids tab, so they update if rows there change.
